<?xml version="1.0" encoding="utf-8"?>
<mujoco model="3D_SLIP">

    <option timestep="0.005" iterations="3" ls_iterations="10" solver="Newton">
        <flag eulerdamp="disable"/>
    </option>

    <!-- Specify the light settings -->
    <visual>
        <headlight diffuse="0.6 0.6 0.6" ambient="0.3 0.3 0.3" specular="0 0 0"/>
        <rgba haze="0.15 0.25 0.35 1"/>
        <global azimuth="150" elevation="-20" offwidth="1920" offheight="1080"/>
    </visual>

    <!-- List the location of all meshes -->
    <asset>
        <mesh file="./meshes/Body.STL" name="com"/>
        <texture type="skybox" builtin="gradient" rgb1="0.3 0.5 0.7" rgb2="0 0 0" width="512" height="3072"/>
        <texture type="2d" name="groundplane" builtin="checker" mark="edge" rgb1="0.2 0.3 0.4" rgb2="0.1 0.2 0.3"
        markrgb="0.8 0.8 0.8" width="300" height="300"/>
        <material name="groundplane" texture="groundplane" texuniform="true" texrepeat="5 5" reflectance="0.2"/>
    </asset>  

    <!-- Set the angles to be in radians -->
    <compiler angle="radian" autolimits="true" eulerseq="zyx"/>

    <!-- Default properties -->
    <default>
        <geom conaffinity="1" contype="1" density="1.0" friction="0.6 0.6 0.6"/>
        <default class="visual">
            <geom conaffinity="0" contype="0"/>
        </default>
    </default>

    <!-- Bodies -->
    <worldbody>
        <!-- Ground -->
        <geom name="plane" type="plane" size="0.0 0.0 0.125" material="groundplane"/>

        <!-- COM Body -->
        <body name="com" pos="0 0 1.0">
            <!-- <freejoint name="root" /> -->
            <joint name="root_x" type="slide" axis="1 0 0"/>
            <joint name="root_y" type="slide" axis="0 1 0"/>
            <joint name="root_z" type="slide" axis="0 0 1"/>

            <!-- A light that tracks the CoM -->
            <light pos="0 0 3" dir="0 0 -1" directional="false" mode="trackcom"/>

            <!-- ixx iyy izz ixy ixz iyz-->
            <!-- <inertial mass="20.0" fullinertia=" 0.045 0.045 0.045 0.0 0.0 0.0" pos="0 0 0" /> -->

            <!-- CoM has sphere collisions but a fancy mesh visual-->
            <geom name="com_mesh" class="visual" mesh="com" type="mesh" rgba="1.0 0.424 0.047 1.0" />
            <geom name="com_collision" type="sphere" size="0.075" rgba="0.0 0.0 0.0 0.0" />

            <!-- Upper Leg -->
            <body name="leg_upper" pos="0 0 -0.15">
                <joint name="leg_pitch" axis="1 0 0" pos="0 0 0.15" limited="true" range="-1.2 1.2"/>
                <joint name="leg_roll" axis="0 1 0" pos="0 0 0.15" limited="true" range="-1.2 1.2"/>
                <geom name="leg_upper" class="visual" type="cylinder" size="0.025 0.15" rgba="0.2 0.2 0.2 0.5"/>

                <!-- Lower Leg -->
                <body name="leg_lower" pos="0 0 -0.15">
                    <joint name="leg_prismatic" axis="0 0 1" type="slide" limited="true" range="-0.15 0.15"/>
                    <geom name="leg_lower" class="visual" type="cylinder" size="0.015 0.15" rgba="1.0 1.0 1.0 0.5"/>

                    <!-- Foot -->
                    <body name="foot" pos="0 0 -0.15">
                        <geom name="foot_sphere" type="sphere" density="0.1" size="0.025" rgba="0 0 0 1.0"/>
                    </body>

                </body>
            </body>
        </body> 
    </worldbody>

    <!-- Actuators -->
    <actuator>
        <position name="leg_pitch" ctrllimited="true" ctrlrange="-1.0 1.0" joint="leg_pitch" kp="0.1" dampratio="1"/>
        <position name="leg_roll" ctrllimited="true" ctrlrange="-1.0 1.0" joint="leg_roll" kp="0.1" dampratio="1"/>
        <position name="leg_prismatic" ctrllimited="true" ctrlrange="-0.15 0.15" joint="leg_prismatic" kp="5" dampratio="0.5"/>
    </actuator>

</mujoco>
